<?xml version="1.0" encoding="utf-8"?>
<robot
        xmlns:xacro="http://www.ros.org/wiki/xacro"
        name="pbot">

    <link
            name="pbot_lf_w">
        <inertial>
            <origin
                    xyz="2.2904E-10 -0.00027973 -1.3045E-10"
                    rpy="0 0 0"/>
            <mass
                    value="0.030238"/>
            <inertia
                    ixx="1.157E-05"
                    ixy="6.3103E-14"
                    ixz="-1.9026E-14"
                    iyy="1.9609E-05"
                    iyz="-5.1829E-14"
                    izz="1.157E-05"/>
        </inertial>
        <visual>
            <origin
                    xyz="0 0 0"
                    rpy="0 0 0"/>
            <geometry>
                <mesh
                        filename="package://pbot_description/meshes/pbot_lf_w.STL"/>
            </geometry>
            <material name="Green"/>
        </visual>
        <collision>
            <origin
                    xyz="0 0 0"
                    rpy="0 0 0"/>
            <geometry>
                <mesh
                        filename="package://pbot_description/meshes/pbot_lf_w.STL"/>
            </geometry>
        </collision>
    </link>
    <joint
            name="pbot_lf_w_to_base"
            type="continuous">
        <origin
                xyz="0.045046 0.0705 -0.013263"
                rpy="0 0.016895 0"/>
        <parent
                link="pbot_base"/>
        <child
                link="pbot_lf_w"/>
        <axis
                xyz="0 -1 0"/>
    </joint>

</robot>