<?xml version="1.0" encoding="utf-8"?>
<robot
        xmlns:xacro="http://www.ros.org/wiki/xacro"
        name="pbot">

    <link
            name="pbot_lr_w">
        <inertial>
            <origin
                    xyz="3.29489630024327E-11 -0.0002797313481048 -1.85563862886706E-10"
                    rpy="0 0 0"/>
            <mass
                    value="0.0302375580133055"/>
            <inertia
                    ixx="1.15702196840428E-05"
                    ixy="-2.03000444280046E-14"
                    ixz="1.06746865771734E-13"
                    iyy="1.96090960377303E-05"
                    iyz="-5.58321097468027E-14"
                    izz="1.15702197584359E-05"/>
        </inertial>
        <visual>
            <origin
                    xyz="0 0 0"
                    rpy="0 0 0"/>
            <geometry>
                <mesh
                        filename="package://pbot_description/meshes/pbot_lr_w.STL"/>
            </geometry>
            <material name="Green"/>
        </visual>
        <collision>
            <origin
                    xyz="0 0 0"
                    rpy="0 0 0"/>
            <geometry>
                <mesh
                        filename="package://pbot_description/meshes/pbot_lr_w.STL"/>
            </geometry>
        </collision>
    </link>
    <joint
            name="pbot_lr_w_to_base"
            type="continuous">
        <origin
                xyz="-0.0728953319370116 0.0705 -0.0112908611194895"
                rpy="0 0.0166094578206921 0"/>
        <parent
                link="pbot_base"/>
        <child
                link="pbot_lr_w"/>
        <axis
                xyz="0 -1 0"/>
    </joint>

</robot>