<?xml version="1.0" encoding="utf-8"?>
<robot
        xmlns:xacro="http://www.ros.org/wiki/xacro"
        name="pbot">

    <link
            name="pbot_rf_w">
        <inertial>
            <origin
                    xyz="7.0441E-11 0.00027973 4.457E-10"
                    rpy="0 0 0"/>
            <mass
                    value="0.030238"/>
            <inertia
                    ixx="1.157E-05"
                    ixy="-7.5717E-15"
                    ixz="-3.0141E-14"
                    iyy="1.9609E-05"
                    iyz="-1.0612E-13"
                    izz="1.157E-05"/>
        </inertial>
        <visual>
            <origin
                    xyz="0 0 0"
                    rpy="0 0 0"/>
            <geometry>
                <mesh
                        filename="package://pbot_description/meshes/pbot_rf_w.STL"/>
            </geometry>
            <material name="Green"/>
        </visual>
        <collision>
            <origin
                    xyz="0 0 0"
                    rpy="0 0 0"/>
            <geometry>
                <mesh
                        filename="package://pbot_description/meshes/pbot_rf_w.STL"/>
            </geometry>
        </collision>
    </link>
    <joint
            name="pbot_rf_w_to_base"
            type="continuous">
        <origin
                xyz="0.047088 -0.0705 -0.013284"
                rpy="0 0.016609 0"/>
        <parent
                link="pbot_base"/>
        <child
                link="pbot_rf_w"/>
        <axis
                xyz="0 1 0"/>
    </joint>
</robot>