<?xml version="1.0" encoding="utf-8"?>

<robot
        xmlns:xacro="http://www.ros.org/wiki/xacro"
        name="pbot">

    <link
            name="pbot_rr_w">
        <inertial>
            <origin
                    xyz="5.38798672344853E-10 0.00027973133311894 5.4071500402153E-10"
                    rpy="0 0 0"/>
            <mass
                    value="0.0302375580628956"/>
            <inertia
                    ixx="1.15702196703268E-05"
                    ixy="-1.34449266129171E-13"
                    ixz="-3.64897808319972E-14"
                    iyy="1.96090960765893E-05"
                    iyz="-1.23593693591465E-13"
                    izz="1.1570219796082E-05"/>
        </inertial>
        <visual>
            <origin
                    xyz="0 0 0"
                    rpy="0 0 0"/>
            <geometry>
                <mesh
                        filename="package://pbot_description/meshes/pbot_rr_w.STL"/>
            </geometry>
            <material name="Green"/>
        </visual>
        <collision>
            <origin
                    xyz="0 0 0"
                    rpy="0 0 0"/>
            <geometry>
                <mesh
                        filename="package://pbot_description/meshes/pbot_rr_w.STL"/>
            </geometry>
        </collision>
    </link>
    <joint
            name="pbot_rr_w_to_base"
            type="continuous">
        <origin
                xyz="-0.0728953319370115 -0.0705 -0.0112908611194895"
                rpy="0 0.0166094578206924 0"/>
        <parent
                link="pbot_base"/>
        <child
                link="pbot_rr_w"/>
        <axis
                xyz="0 1 0"/>
    </joint>

</robot>