<?xml version="1.0" encoding="utf-8"?>
<robot
        xmlns:xacro="http://www.ros.org/wiki/xacro"
        name="pbot">
    <link
            name="pbot_lr_w">
        <inertial>
            <origin
                    xyz="-1.3858E-10 -0.00027973 1.3827E-10"
                    rpy="0 0 0"/>
            <mass
                    value="0.030238"/>
            <inertia
                    ixx="1.157E-05"
                    ixy="-3.977E-14"
                    ixz="5.9664E-14"
                    iyy="1.9609E-05"
                    iyz="1.6868E-14"
                    izz="1.157E-05"/>
        </inertial>
        <visual>
            <origin
                    xyz="0 0 0"
                    rpy="0 0 0"/>
            <geometry>
                <mesh
                        filename="package://pbot_description/meshes/pbot_lr_w.STL"/>
            </geometry>
            <material name="Green"/>
        </visual>
        <collision>
            <origin
                    xyz="0 0 0"
                    rpy="0 0 0"/>
            <geometry>
                <mesh
                        filename="package://pbot_description/meshes/pbot_lr_w.STL"/>
            </geometry>
        </collision>
    </link>
    <joint
            name="pbot_lr_w_to_base"
            type="continuous">
        <origin
                xyz="-0.074937 0.0705 -0.011236"
                rpy="0 0.016895 0"/>
        <parent
                link="pbot_base"/>
        <child
                link="pbot_lr_w"/>
        <axis
                xyz="0 -1 0"/>
    </joint>
</robot>